Workbook

Sheet Datos
A1: Fecha | B1: NIS | C1: Cliente | D1: IVA | E1: Consumo [kWh] | F1: Consumo hs punta [kWh] | G1: Consumo hs valle [kWh] | H1: Consumo hs resto[kWh] | I1: Catergoria | J1: Tarifa punta | K1: Tarifa valle | L1: Tarifa resto | M1: Generacion FV [kWh] | N1: CONSUMO TOTAL | O1: Total a pagar S / IVA | P1: Valor USD | Q1: Ahorro (USD) | R1: Ahorro ($) | S1: Valor dolar Actual ($) | T1: Ahorro ($)-A precio actual | U1: kg CO2e evitados | V1: Equivalente en árboles | W1: % de ahorro sobre los consumos | X1: SIN PANELES S/IVA
A2: 45992 | B2: 5296128 | C2: Fabrica Forja | D2: 0.27 | E2: 1420 | F2: 170 | G2: 301 | H2: 949 | I2: T2-Ba | J2: 148.2814 | K2: 148.2814 | L2: 148.2814 | M2: 270 | N2: =E2+M2 -> 1690 | O2: =J2*F2+G2*K2+H2*L2 -> 210559.59 | P2: 1470 | Q2: =(M2*L2)/P2 -> 27.235359 | R2: =Q2*P2 -> 40035.978 | S2: =IFERROR(__xludf.DUMMYFUNCTION("INDEX(IMPORTHTML(""https://www.bna.com.ar/Personas"", ""table"", 1), 2, 3)"),1465.0) -> 1465 | T2: =Q2*S2*(1+D2) -> 50672.748 | U2: =M2*0.2 -> 54 | V2: =U2/22 -> 2.4545455 | W2: =(M2*L2)/(M2*L2+H2*L2+K2*G2+J2*F2) -> 0.15976331 | X2: =F2*J2+G2*K2+H2*L2+M2*L2 -> 250595.57
A3: 45993 | B3: 5238545 | C3: Cendis | D3: 0.27 | E3: =SUM(F3:H3) -> 46318 | F3: 11250 | G3: 11963 | H3: 23105 | I3: T5-Ba | J3: 168.7698 | K3: 165.9802 | L3: 166.7828 | M3: 13451.7 | N3: =E3+M3 -> 59769.7 | O3: =J3*F3+G3*K3+H3*L3 -> 7737798 | P3: 1470 | Q3: =(M3*L3)/P3 -> 1526.1988 | R3: =Q3*P3 -> 2243512.2 | S3: =IFERROR(__xludf.DUMMYFUNCTION("INDEX(IMPORTHTML(""https://www.bna.com.ar/Personas"", ""table"", 1), 2, 3)"),1465.0) -> 1465 | T3: =Q3*S3*(1+D3) -> 2839569.1 | U3: =M3*0.2 -> 2690.34 | V3: =U3/22 -> 122.28818 | W3: =(M3*L3)/(M3*L3+H3*L3+K3*G3+J3*F3) -> 0.22477131 | X3: =F3*J3+G3*K3+H3*L3+M3*L3 -> 9981310.2
A4: 45994 | B4: 5076526 | C4: Martin Lecuona | D4: 0.27 | E4: =SUM(F4:H4) -> 4410 | F4: 30 | G4: 570 | H4: 3810 | I4: T4-Ba | J4: 152.0913 | K4: 153.7589 | L4: 154.5615
A5: 45992 | B5: 5347980 | C5: Nallim Jose Carlos | D5: 0.27 | E5: 577 | F5: 0 | G5: 0 | H5: , | I5: T1-R2-N1 | J5: 233.1878 | K5: 233.1878 | L5: 233.1878 | M5: 80.9 | N5: =E5+M5 -> 657.9 | O5: =J5*F5+G5*K5+H5*L5 -> #VALUE! | P5: 1470 | Q5: =(M5*L5)/P5 -> 12.833261 | R5: =Q5*P5 -> 18864.893 | S5: =IFERROR(__xludf.DUMMYFUNCTION("INDEX(IMPORTHTML(""https://www.bna.com.ar/Personas"", ""table"", 1), 2, 3)"),1465.0) -> 1465 | T5: =Q5*S5*(1+D5) -> 23876.923 | U5: =M5*0.2 -> 16.18 | V5: =U5/22 -> 0.73545455 | W5: =(M5*L5)/(M5*L5+H5*L5+K5*G5+J5*F5) -> #VALUE! | X5: =F5*J5+G5*K5+H5*L5+M5*L5 -> #VALUE!
A6: 45992 | B6: 5263215 | C6: Distribuidora Maestro | D6: 0.27 | E6: 2403 | F6: 0 | G6: 0 | H6: 2403 | I6: T1-G2 | J6: 195.2987 | K6: 195.2987 | L6: 195.2987 | M6: 1342.3 | N6: =E6+M6 -> 3745.3 | O6: =J6*F6+G6*K6+H6*L6 -> 469302.78 | P6: 1470 | Q6: =(M6*L6)/P6 -> 178.33296 | R6: =Q6*P6 -> 262149.45 | S6: =IFERROR(__xludf.DUMMYFUNCTION("INDEX(IMPORTHTML(""https://www.bna.com.ar/Personas"", ""table"", 1), 2, 3)"),1465.0) -> 1465 | T6: =Q6*S6*(1+D6) -> 331797.38 | U6: =M6*0.2 -> 268.46 | V6: =U6/22 -> 12.202727 | W6: =(M6*L6)/(M6*L6+H6*L6+K6*G6+J6*F6) -> 0.35839586 | X6: =F6*J6+G6*K6+H6*L6+M6*L6 -> 731452.22
A7: 45992 | B7: 3025373 | C7: Agustín Sanz Navamuel | D7: 0.27 | E7: 37973 | F7: 9357 | G7: 11035 | H7: 17581 | I7: T8 | J7: 255.886 | K7: 253.0963 | L7: 253.899 | M7: 6304.4 | N7: =E7+M7 -> 44277.4 | O7: =J7*F7+G7*K7+H7*L7 -> 9651041.3 | P7: 1470 | Q7: =(M7*L7)/P7 -> 1088.8985 | R7: =Q7*P7 -> 1600680.9 | S7: =IFERROR(__xludf.DUMMYFUNCTION("INDEX(IMPORTHTML(""https://www.bna.com.ar/Personas"", ""table"", 1), 2, 3)"),1465.0) -> 1465 | T7: =Q7*S7*(1+D7) -> 2025950.2 | U7: =M7*0.2 -> 1260.88 | V7: =U7/22 -> 57.312727 | W7: =(M7*L7)/(M7*L7+H7*L7+K7*G7+J7*F7) -> 0.14226097 | X7: =F7*J7+G7*K7+H7*L7+M7*L7 -> 11251722
A8: 45992 | B8: 5346222 | C8: O.Domingo-Arenosa | D8: 0.27 | E8: 3833 | F8: 998 | G8: 554 | H8: 2281 | I8: T2-Ba | J8: 148.2814 | K8: 148.2814 | L8: 148.2814 | M8: 3122.4 | N8: =E8+M8 -> 6955.4 | O8: =J8*F8+G8*K8+H8*L8 -> 568362.61 | P8: 1470 | Q8: =(M8*L8)/P8 -> 314.9618 | R8: =Q8*P8 -> 462993.84 | S8: =IFERROR(__xludf.DUMMYFUNCTION("INDEX(IMPORTHTML(""https://www.bna.com.ar/Personas"", ""table"", 1), 2, 3)"),1465.0) -> 1465 | T8: =Q8*S8*(1+D8) -> 586002.17 | U8: =M8*0.2 -> 624.48 | V8: =U8/22 -> 28.385455 | W8: =(M8*L8)/(M8*L8+H8*L8+K8*G8+J8*F8) -> 0.44891739 | X8: =F8*J8+G8*K8+H8*L8+M8*L8 -> 1031356.4
A9: 45992 | B9: 5211887 | C9: O.Domingo-Colectivo | D9: 0.27 | E9: 2829 | F9: 0 | G9: 0 | H9: 2829 | I9: T2-Ba | J9: 148.2814 | K9: 148.2814 | L9: 148.2814 | M9: 1272.1 | N9: =E9+M9 -> 4101.1 | O9: =J9*F9+G9*K9+H9*L9 -> 419488.08 | P9: 1470 | Q9: =(M9*L9)/P9 -> 128.31889 | R9: =Q9*P9 -> 188628.77 | S9: =IFERROR(__xludf.DUMMYFUNCTION("INDEX(IMPORTHTML(""https://www.bna.com.ar/Personas"", ""table"", 1), 2, 3)"),1465.0) -> 1465 | T9: =Q9*S9*(1+D9) -> 238743.71 | U9: =M9*0.2 -> 254.42 | V9: =U9/22 -> 11.564545 | W9: =(M9*L9)/(M9*L9+H9*L9+K9*G9+J9*F9) -> 0.31018507 | X9: =F9*J9+G9*K9+H9*L9+M9*L9 -> 608116.85
A10: 45992 | B10: 5253775 | C10: Joaquín Elizalde | D10: 0.21 | E10: 542 | F10: 0 | G10: 0 | H10: 542 | I10: T1-R2-N1 | J10: 240.5281 | K10: 240.5281 | L10: 240.5281 | M10: 138.3 | N10: =E10+M10 -> 680.3 | O10: =J10*F10+G10*K10+H10*L10 -> 130366.23 | P10: 1470 | Q10: =(M10*L10)/P10 -> 22.629276 | R10: =Q10*P10 -> 33265.036 | S10: =IFERROR(__xludf.DUMMYFUNCTION("INDEX(IMPORTHTML(""https://www.bna.com.ar/Personas"", ""table"", 1), 2, 3)"),1465.0) -> 1465 | T10: =Q10*S10*(1+D10) -> 40113.787 | U10: =M10*0.2 -> 27.66 | V10: =U10/22 -> 1.2572727 | W10: =(M10*L10)/(M10*L10+H10*L10+K10*G10+J10*F10) -> 0.20329267 | X10: =F10*J10+G10*K10+H10*L10+M10*L10 -> 163631.27
A11: 45992 | B11: 4000681 | C11: O.Domingo-Animana | D11: 0.27 | E11: 8034 | F11: 2164 | G11: 2756 | H11: 3114 | I11: T2-Ba | J11: 148.2814 | K11: 148.2814 | L11: 148.2814 | M11: 2746.1 | N11: =E11+M11 -> 10780.1 | O11: =J11*F11+G11*K11+H11*L11 -> 1191292.8 | P11: 1470 | Q11: =(M11*L11)/P11 -> 277.00378 | R11: =Q11*P11 -> 407195.55 | S11: =IFERROR(__xludf.DUMMYFUNCTION("INDEX(IMPORTHTML(""https://www.bna.com.ar/Personas"", ""table"", 1), 2, 3)"),1465.0) -> 1465 | T11: =Q11*S11*(1+D11) -> 515379.38 | U11: =M11*0.2 -> 549.22 | V11: =U11/22 -> 24.964545 | W11: =(M11*L11)/(M11*L11+H11*L11+K11*G11+J11*F11) -> 0.2547379 | X11: =F11*J11+G11*K11+H11*L11+M11*L11 -> 1598488.3
A12: 45992 | B12: 5076619 | C12: LaMerceddelAlto | D12: 0.27 | E12: 3196 | F12: 1096 | G12: 841 | H12: 1259 | I12: T2-Ba | J12: 148.2814 | K12: 148.2814 | L12: 148.2814 | N12: =E12+M12 -> 3196 | O12: =J12*F12+G12*K12+H12*L12 -> 473907.35 | P12: 1470 | Q12: =(M12*L12)/P12 -> 0 | R12: =Q12*P12 -> 0 | S12: =IFERROR(__xludf.DUMMYFUNCTION("INDEX(IMPORTHTML(""https://www.bna.com.ar/Personas"", ""table"", 1), 2, 3)"),1465.0) -> 1465 | T12: =Q12*S12*(1+D12) -> 0 | U12: =M12*0.2 -> 0 | V12: =U12/22 -> 0 | W12: =(M12*L12)/(M12*L12+H12*L12+K12*G12+J12*F12) -> 0 | X12: =F12*J12+G12*K12+H12*L12+M12*L12 -> 473907.35
A13: 45992 | B13: 3092029 | C13: Farmacia San Francisco | D13: 0.27 | E13: 14100 | F13: 4050 | G13: 2100 | H13: 7950 | I13: T4-Ba | J13: 156.5485 | K13: 153.7589 | L13: 154.5615 | M13: 3220 | N13: =E13+M13 -> 17320 | O13: =J13*F13+G13*K13+H13*L13 -> 2185679 | P13: 1470 | Q13: =(M13*L13)/P13 -> 338.56329 | R13: =Q13*P13 -> 497688.03 | S13: =IFERROR(__xludf.DUMMYFUNCTION("INDEX(IMPORTHTML(""https://www.bna.com.ar/Personas"", ""table"", 1), 2, 3)"),1465.0) -> 1465 | T13: =Q13*S13*(1+D13) -> 629913.92 | U13: =M13*0.2 -> 644 | V13: =U13/22 -> 29.272727 | W13: =(M13*L13)/(M13*L13+H13*L13+K13*G13+J13*F13) -> 0.18547147 | X13: =F13*J13+G13*K13+H13*L13+M13*L13 -> 2683367.1
A14: 45992 | B14: 5253773 | C14: Ivan BV | D14: 0.21 | E14: 365 | F14: 116 | G14: 91 | H14: 158 | I14: T1-R2-N1 | J14: 229.3919 | K14: 229.3919 | L14: 229.3919 | M14: 163 | N14: =E14+M14 -> 528 | O14: =J14*F14+G14*K14+H14*L14 -> 83728.043 | P14: 1470 | Q14: =(M14*L14)/P14 -> 25.435973 | R14: =Q14*P14 -> 37390.88 | S14: =IFERROR(__xludf.DUMMYFUNCTION("INDEX(IMPORTHTML(""https://www.bna.com.ar/Personas"", ""table"", 1), 2, 3)"),1465.0) -> 1465 | T14: =Q14*S14*(1+D14) -> 45089.077 | U14: =M14*0.2 -> 32.6 | V14: =U14/22 -> 1.4818182 | W14: =(M14*L14)/(M14*L14+H14*L14+K14*G14+J14*F14) -> 0.30871212 | X14: =F14*J14+G14*K14+H14*L14+M14*L14 -> 121118.92
A15: 45992 | B15: 5238577 | C15: Agustín Lanús | D15: 0.27 | E15: 6223 | F15: 0 | G15: 0 | H15: 6223 | I15: T2-Ba | J15: 148.2814 | K15: 148.2814 | L15: 148.2814 | M15: 1543.5 | N15: =E15+M15 -> 7766.5 | O15: =J15*F15+G15*K15+H15*L15 -> 922755.15 | P15: 1470 | Q15: =(M15*L15)/P15 -> 155.69547 | R15: =Q15*P15 -> 228872.34 | S15: =IFERROR(__xludf.DUMMYFUNCTION("INDEX(IMPORTHTML(""https://www.bna.com.ar/Personas"", ""table"", 1), 2, 3)"),1465.0) -> 1465 | T15: =Q15*S15*(1+D15) -> 289679.21 | U15: =M15*0.2 -> 308.7 | V15: =U15/22 -> 14.031818 | W15: =(M15*L15)/(M15*L15+H15*L15+K15*G15+J15*F15) -> 0.19873817 | X15: =F15*J15+G15*K15+H15*L15+M15*L15 -> 1151627.5
A16: 45992 | B16: 5272486 | C16: Linea C | D16: 0.27 | E16: 4539 | F16: 0 | G16: 0 | H16: 4539 | I16: T1-G2 | J16: 195.2987 | K16: 195.2987 | L16: 195.2987 | M16: 1113.6 | N16: =E16+M16 -> 5652.6 | O16: =J16*F16+G16*K16+H16*L16 -> 886460.8 | P16: 1470 | Q16: =(M16*L16)/P16 -> 147.94873 | R16: =Q16*P16 -> 217484.63 | S16: =IFERROR(__xludf.DUMMYFUNCTION("INDEX(IMPORTHTML(""https://www.bna.com.ar/Personas"", ""table"", 1), 2, 3)"),1465.0) -> 1465 | T16: =Q16*S16*(1+D16) -> 275266.01 | U16: =M16*0.2 -> 222.72 | V16: =U16/22 -> 10.123636 | W16: =(M16*L16)/(M16*L16+H16*L16+K16*G16+J16*F16) -> 0.19700669 | X16: =F16*J16+G16*K16+H16*L16+M16*L16 -> 1103945.4
A17: 45992 | B17: 5019237 | C17: Etchart | D17: 0.27 | E17: 2950 | F17: 684 | G17: 810 | H17: 1456 | I17: T4-Ba | J17: 156.5485 | K17: 153.7589 | L17: 154.5615 | M17: 1063.3 | N17: =E17+M17 -> 4013.3 | O17: =J17*F17+G17*K17+H17*L17 -> 456665.43 | P17: 1470 | Q17: =(M17*L17)/P17 -> 111.79949 | R17: =Q17*P17 -> 164345.24 | S17: =IFERROR(__xludf.DUMMYFUNCTION("INDEX(IMPORTHTML(""https://www.bna.com.ar/Personas"", ""table"", 1), 2, 3)"),1465.0) -> 1465 | T17: =Q17*S17*(1+D17) -> 208008.53 | U17: =M17*0.2 -> 212.66 | V17: =U17/22 -> 9.6663636 | W17: =(M17*L17)/(M17*L17+H17*L17+K17*G17+J17*F17) -> 0.26464158 | X17: =F17*J17+G17*K17+H17*L17+M17*L17 -> 621010.67
A18: 45962 | B18: 5068576 | C18: Facundo Alvarado | D18: 0.27 | E18: 13501 | F18: 2929 | G18: 3482 | H18: 7090 | I18: T4-Ba | J18: 152.0913 | K18: 149.3017 | L18: 150.1043 | M18: 3862.5 | N18: =E18+M18 -> 17363.5 | O18: =J18*F18+G18*K18+H18*L18 -> 2029583.4 | P18: 1470 | Q18: =(M18*L18)/P18 -> 394.40671 | R18: =Q18*P18 -> 579777.86 | S18: =IFERROR(__xludf.DUMMYFUNCTION("INDEX(IMPORTHTML(""https://www.bna.com.ar/Personas"", ""table"", 1), 2, 3)"),1465.0) -> 1465 | T18: =Q18*S18*(1+D18) -> 733813.4 | U18: =M18*0.2 -> 772.5 | V18: =U18/22 -> 35.113636 | W18: =(M18*L18)/(M18*L18+H18*L18+K18*G18+J18*F18) -> 0.22219149 | X18: =F18*J18+G18*K18+H18*L18+M18*L18 -> 2609361.3
A19: 45992 | B19: 5214767 | C19: La Carolina | D19: 0.27 | E19: 6345 | F19: 1180 | G19: 343 | H19: 4822 | I19: T2-Ba | J19: 148.2814 | K19: 148.2814 | L19: 148.2814 | M19: 5109.8 | N19: =E19+M19 -> 11454.8 | O19: =J19*F19+G19*K19+H19*L19 -> 940845.48 | P19: 1470 | Q19: =(M19*L19)/P19 -> 515.43422 | R19: =Q19*P19 -> 757688.3 | S19: =IFERROR(__xludf.DUMMYFUNCTION("INDEX(IMPORTHTML(""https://www.bna.com.ar/Personas"", ""table"", 1), 2, 3)"),1465.0) -> 1465 | T19: =Q19*S19*(1+D19) -> 958991.13 | U19: =M19*0.2 -> 1021.96 | V19: =U19/22 -> 46.452727 | W19: =(M19*L19)/(M19*L19+H19*L19+K19*G19+J19*F19) -> 0.44608374 | X19: =F19*J19+G19*K19+H19*L19+M19*L19 -> 1698533.8
A20: 45992 | B20: 5346470 | C20: Punto Corp | D20: 0.27 | E20: 6144 | F20: 1770 | G20: 1962 | H20: 2412 | I20: T4-Ba | J20: 156.5485 | K20: 153.7589 | L20: 154.5615 | M20: 2452.2 | N20: =E20+M20 -> 8596.2 | O20: =J20*F20+G20*K20+H20*L20 -> 951568.14 | P20: 1470 | Q20: =(M20*L20)/P20 -> 257.83382 | R20: =Q20*P20 -> 379015.71 | S20: =IFERROR(__xludf.DUMMYFUNCTION("INDEX(IMPORTHTML(""https://www.bna.com.ar/Personas"", ""table"", 1), 2, 3)"),1465.0) -> 1465 | T20: =Q20*S20*(1+D20) -> 479712.71 | U20: =M20*0.2 -> 490.44 | V20: =U20/22 -> 22.292727 | W20: =(M20*L20)/(M20*L20+H20*L20+K20*G20+J20*F20) -> 0.28484917 | X20: =F20*J20+G20*K20+H20*L20+M20*L20 -> 1330583.9
A21: 45992 | B21: 5213946 | C21: Tambo Martorell | D21: 0.27 | E21: 6604 | F21: 2584 | G21: 869 | H21: 3151 | I21: T6-Me | J21: 174.6648 | K21: 172.155 | L21: 172.8771 | M21: 1179.2 | N21: =E21+M21 -> 7783.2 | O21: =J21*F21+G21*K21+H21*L21 -> 1145672.3 | P21: 1470 | Q21: =(M21*L21)/P21 -> 138.67801 | R21: =Q21*P21 -> 203856.68 | S21: =IFERROR(__xludf.DUMMYFUNCTION("INDEX(IMPORTHTML(""https://www.bna.com.ar/Personas"", ""table"", 1), 2, 3)"),1465.0) -> 1465 | T21: =Q21*S21*(1+D21) -> 258017.37 | U21: =M21*0.2 -> 235.84 | V21: =U21/22 -> 10.72 | W21: =(M21*L21)/(M21*L21+H21*L21+K21*G21+J21*F21) -> 0.15105765 | X21: =F21*J21+G21*K21+H21*L21+M21*L21 -> 1349529
A22: 45992 | B22: 5251104 | C22: Cartoon Inversor 1 | D22: 0.27 | E22: 12507 | F22: 1173 | G22: 215 | H22: 11119 | I22: T5-Ba | J22: 168.7698 | K22: 165.9802 | L22: 166.7828 | M22: 5243.9 | N22: =E22+M22 -> 17750.9 | O22: =J22*F22+G22*K22+H22*L22 -> 2088110.7 | P22: 1470 | Q22: =(M22*L22)/P22 -> 594.96077 | R22: =Q22*P22 -> 874592.32 | S22: =IFERROR(__xludf.DUMMYFUNCTION("INDEX(IMPORTHTML(""https://www.bna.com.ar/Personas"", ""table"", 1), 2, 3)"),1465.0) -> 1465 | T22: =Q22*S22*(1+D22) -> 1106954.3 | U22: =M22*0.2 -> 1048.78 | V22: =U22/22 -> 47.671818 | W22: =(M22*L22)/(M22*L22+H22*L22+K22*G22+J22*F22) -> 0.29520081 | X22: =F22*J22+G22*K22+H22*L22+M22*L22 -> 2962703
A23: 45992 | B23: 5251101 | C23: Cartoon Inversor 2 | D23: 0.27 | E23: 4392 | F23: 852 | G23: 324 | H23: 3216 | I23: T5-Ba | J23: 168.7698 | K23: 165.9802 | L23: 166.7828 | M23: 3063.6 | N23: =E23+M23 -> 7455.6 | O23: =J23*F23+G23*K23+H23*L23 -> 733942.94 | P23: 1470 | Q23: =(M23*L23)/P23 -> 347.58897 | R23: =Q23*P23 -> 510955.79 | S23: =IFERROR(__xludf.DUMMYFUNCTION("INDEX(IMPORTHTML(""https://www.bna.com.ar/Personas"", ""table"", 1), 2, 3)"),1465.0) -> 1465 | T23: =Q23*S23*(1+D23) -> 646706.66 | U23: =M23*0.2 -> 612.72 | V23: =U23/22 -> 27.850909 | W23: =(M23*L23)/(M23*L23+H23*L23+K23*G23+J23*F23) -> 0.41043964 | X23: =F23*J23+G23*K23+H23*L23+M23*L23 -> 1244898.7
A24: 45992 | B24: 3011513 | C24: Robles | D24: 0.27 | E24: 28047 | F24: 7969 | G24: 9368 | H24: 10710 | I24: T8 | J24: 255.886 | K24: 253.0963 | L24: 253.899 | M24: 10816.3 | N24: =E24+M24 -> 38863.3 | O24: =J24*F24+G24*K24+H24*L24 -> 7129420 | P24: 1470 | Q24: =(M24*L24)/P24 -> 1868.1958 | R24: =Q24*P24 -> 2746247.8 | S24: =IFERROR(__xludf.DUMMYFUNCTION("INDEX(IMPORTHTML(""https://www.bna.com.ar/Personas"", ""table"", 1), 2, 3)"),1465.0) -> 1465 | T24: =Q24*S24*(1+D24) -> 3475871.6 | U24: =M24*0.2 -> 2163.26 | V24: =U24/22 -> 98.33 | W24: =(M24*L24)/(M24*L24+H24*L24+K24*G24+J24*F24) -> 0.27808224 | X24: =F24*J24+G24*K24+H24*L24+M24*L24 -> 9875667.7
... A26: 45992 | B26: 4000202 | C26: Diagnostico Salta | D26: 0.27 | E26: 16520 | F26: 4270 | G26: 3920 | H26: 8330 | I26: T4-Ba | J26: 156.5485 | K26: 153.7589 | L26: 154.5615 | M26: 4092.3 | N26: =E26+M26 -> 20612.3 | O26: =J26*F26+G26*K26+H26*L26 -> 2558694.3 | P26: 1470 | Q26: =(M26*L26)/P26 -> 430.28029 | R26: =Q26*P26 -> 632512.03 | S26: =IFERROR(__xludf.DUMMYFUNCTION("INDEX(IMPORTHTML(""https://www.bna.com.ar/Personas"", ""table"", 1), 2, 3)"),1465.0) -> 1465 | T26: =Q26*S26*(1+D26) -> 800557.99 | U26: =M26*0.2 -> 818.46 | V26: =U26/22 -> 37.202727 | W26: =(M26*L26)/(M26*L26+H26*L26+K26*G26+J26*F26) -> 0.19820468 | X26: =F26*J26+G26*K26+H26*L26+M26*L26 -> 3191206.3
A27: 45962 | B27: 4000202 | C27: Diagnostico Salta | D27: 0.27 | E27: =SUM(F27:H27) -> 15680 | F27: 4130 | G27: 3780 | H27: 7770 | I27: T4-Ba | J27: 152.0913 | K27: 149.3017 | L27: 150.1043 | M27: 3980.5 | N27: =E27+M27 -> 19660.5 | O27: =J27*F27+G27*K27+H27*L27 -> 2358807.9 | P27: 1470 | Q27: =(M27*L27)/P27 -> 406.4559 | R27: =Q27*P27 -> 597490.17 | S27: =IFERROR(__xludf.DUMMYFUNCTION("INDEX(IMPORTHTML(""https://www.bna.com.ar/Personas"", ""table"", 1), 2, 3)"),1465.0) -> 1465 | T27: =Q27*S27*(1+D27) -> 756231.52 | U27: =M27*0.2 -> 796.1 | V27: =U27/22 -> 36.186364 | W27: =(M27*L27)/(M27*L27+H27*L27+K27*G27+J27*F27) -> 0.20210755 | X27: =F27*J27+G27*K27+H27*L27+M27*L27 -> 2956298.1
A28: 45963 | B28: 5238545 | C28: Cendis | D28: 0.27 | E28: =SUM(F28:H28) -> 35146 | F28: 9214 | G28: 9096 | H28: 16836 | I28: T5-Ba | J28: 163.3724 | K28: 160.5827 | L28: 161.3854 | M28: 12463.3 | N28: =E28+M28 -> 47609.3 | O28: =J28*F28+G28*K28+H28*L28 -> 5683058.1 | P28: 1470 | Q28: =(M28*L28)/P28 -> 1368.2957 | R28: =Q28*P28 -> 2011394.7 | S28: =IFERROR(__xludf.DUMMYFUNCTION("INDEX(IMPORTHTML(""https://www.bna.com.ar/Personas"", ""table"", 1), 2, 3)"),1465.0) -> 1465 | T28: =Q28*S28*(1+D28) -> 2545782.5 | U28: =M28*0.2 -> 2492.66 | V28: =U28/22 -> 113.30273 | W28: =(M28*L28)/(M28*L28+H28*L28+K28*G28+J28*F28) -> 0.26140841 | X28: =F28*J28+G28*K28+H28*L28+M28*L28 -> 7694452.8
A29: 45964 | B29: 5263215 | C29: Distribuidora Maestro | D29: 0.27 | E29: =SUM(F29:H29) -> 2199 | H29: 2199 | I29: T1-G2 | J29: 195.1016 | K29: 195.1016 | L29: 195.1016 | M29: 1232.2 | N29: =E29+M29 -> 3431.2 | O29: =J29*F29+G29*K29+H29*L29 -> 429028.42 | P29: 1470 | Q29: =(M29*L29)/P29 -> 163.54027 | R29: =Q29*P29 -> 240404.19 | S29: =IFERROR(__xludf.DUMMYFUNCTION("INDEX(IMPORTHTML(""https://www.bna.com.ar/Personas"", ""table"", 1), 2, 3)"),1465.0) -> 1465 | T29: =Q29*S29*(1+D29) -> 304274.84 | U29: =M29*0.2 -> 246.44 | V29: =U29/22 -> 11.201818 | W29: =(M29*L29)/(M29*L29+H29*L29+K29*G29+J29*F29) -> 0.35911634 | X29: =F29*J29+G29*K29+H29*L29+M29*L29 -> 669432.61
A30: 45965 | B30: 5296128 | C30: Fabrica Forja | D30: 0.27 | E30: =SUM(F30:H30) -> 1461 | F30: 162 | G30: 268 | H30: 1031 | I30: T2-Ba | J30: 145.8675 | K30: 145.8675 | L30: 145.8675 | M30: 337.8 | N30: =E29+M30 -> 2536.8 | O30: =J30*F30+G30*K30+H30*L30 -> 213112.42 | P30: 1470 | Q30: =(M30*L30)/P30 -> 33.519756 | R30: =Q30*P30 -> 49274.041 | S30: =IFERROR(__xludf.DUMMYFUNCTION("INDEX(IMPORTHTML(""https://www.bna.com.ar/Personas"", ""table"", 1), 2, 3)"),1465.0) -> 1465 | T30: =Q30*S30*(1+D30) -> 62365.182 | U30: =M30*0.2 -> 67.56 | V30: =U30/22 -> 3.0709091 | W30: =(M30*L30)/(M30*L30+H30*L30+K30*G30+J30*F30) -> 0.18779186 | X30: =F30*J30+G30*K30+H30*L30+M30*L30 -> 262386.46
A31: 45966 | B31: 3062898 | C31: Tolaba | D31: 0.27 | E31: =SUM(F31:H31) -> 7178 | F31: 1742 | G31: 1984 | H31: 3452 | I31: T8 | J31: 253.749 | K31: 251.0043 | L31: 251.807 | M31: 1018.2 | N31: =F31+M31 -> 2760.2 | O31: =J31*F31+G31*K31+H31*L31 -> 1809261.1 | P31: 1470 | Q31: =(M31*L31)/P31 -> 174.41489 | R31: =Q31*P31 -> 256389.89 | S31: =IFERROR(__xludf.DUMMYFUNCTION("INDEX(IMPORTHTML(""https://www.bna.com.ar/Personas"", ""table"", 1), 2, 3)"),1465.0) -> 1465 | T31: =Q31*S31*(1+D31) -> 324507.62 | U31: =M31*0.2 -> 203.64 | V31: =U31/22 -> 9.2563636 | W31: =(M31*L31)/(M31*L31+H31*L31+K31*G31+J31*F31) -> 0.12412063 | X31: =F31*J31+G31*K31+H31*L31+M31*L31 -> 2065650.9
A32: 45967 | B32: 3011513 | C32: Robles | D32: 0.27 | E32: =SUM(F32:H32) -> 691 | F32: 208 | G32: 207 | H32: 276 | I32: T8 | J32: 253.749 | K32: 251.0043 | L32: 251.807 | M32: 632.2 | N32: =E32+M32 -> 1323.2 | O32: =J33*F32+G32*K33+H32*L33 -> 103969.23 | P32: 1470 | Q32: =(M32*L33)/P32 -> 64.55506 | R32: =Q32*P32 -> 94895.938 | S32: =IFERROR(__xludf.DUMMYFUNCTION("INDEX(IMPORTHTML(""https://www.bna.com.ar/Personas"", ""table"", 1), 2, 3)"),1465.0) -> 1465 | T32: =Q32*S32*(1+D32) -> 120107.92 | U32: =M32*0.2 -> 126.44 | V32: =U32/22 -> 5.7472727 | W32: =(M32*L33)/(M32*L33+H32*L33+K33*G32+J33*F32) -> 0.47718733 | X32: =F32*J33+G32*K33+H32*L33+M32*L33 -> 198865.17
A33: 45968 | B33: 5076526 | C33: Martín Lecuona | D33: 0.27 | E33: =SUM(F33:H33) -> 6180 | F33: 30 | G33: 2130 | H33: 4020 | I33: T4-Ba | J33: 152.0913 | K33: 149.3017 | L33: 150.1043 | M33: 1905.7 | N33: =F33+M33 -> 1935.7 | O33: =J34*F33+G33*K34+H33*L34 -> 1025984.8 | P33: 1470 | Q33: =(M33*L34)/P33 -> 215.53493 | R33: =Q33*P33 -> 316836.35 | S33: =IFERROR(__xludf.DUMMYFUNCTION("INDEX(IMPORTHTML(""https://www.bna.com.ar/Personas"", ""table"", 1), 2, 3)"),1465.0) -> 1465 | T33: =Q33*S33*(1+D33) -> 401013.51 | U33: =M33*0.2 -> 381.14 | V33: =U33/22 -> 17.324545 | W33: =(M33*L34)/(M33*L34+H33*L34+K34*G33+J34*F33) -> 0.23594828 | X33: =F33*J34+G33*K34+H33*L34+M33*L34 -> 1342821.2
A34: 45969 | B34: 5213946 | C34: Tambo Martorell | D34: 0.27 | E34: =SUM(F34:H34) -> 5951 | F34: 2497 | G34: 732 | H34: 2722 | I34: T6-Me | J34: 168.0449 | K34: 165.535 | L34: 166.2572 | M34: 1195.1 | N34: =E34+M34 -> 7146.1 | O34: =J34*F34+G34*K34+H34*L34 -> 993331.83 | P34: 1470 | Q34: =(M34*L34)/P34 -> 135.16597 | R34: =Q34*P34 -> 198693.98 | S34: =IFERROR(__xludf.DUMMYFUNCTION("INDEX(IMPORTHTML(""https://www.bna.com.ar/Personas"", ""table"", 1), 2, 3)"),1465.0) -> 1465 | T34: =Q34*S34*(1+D34) -> 251483.05 | U34: =M34*0.2 -> 239.02 | V34: =U34/22 -> 10.864545 | W34: =(M34*L34)/(M34*L34+H34*L34+K34*G34+J34*F34) -> 0.16668597 | X34: =F34*J34+G34*K34+H34*L34+M34*L34 -> 1192025.8
A35: 45970 | B35: 5346470 | C35: Punto Corp | D35: 0.27 | E35: =SUM(F35:H35) -> 5553 | F35: 1722 | G35: 1962 | H35: 1869 | I35: T4-Ba | J35: 152.0913 | K35: 149.3017 | L35: 150.1043 | M35: 2814.1 | N35: =E35+M35 -> 8367.1 | O35: =J35*F35+G35*K35+H35*L35 -> 835376.09 | P35: 1470 | Q35: =(M35*L35)/P35 -> 287.35273 | R35: =Q35*P35 -> 422408.51 | S35: =IFERROR(__xludf.DUMMYFUNCTION("INDEX(IMPORTHTML(""https://www.bna.com.ar/Personas"", ""table"", 1), 2, 3)"),1465.0) -> 1465 | T35: =Q35*S35*(1+D35) -> 534634.12 | U35: =M35*0.2 -> 562.82 | V35: =U35/22 -> 25.582727 | W35: =(M35*L35)/(M35*L35+H35*L35+K35*G35+J35*F35) -> 0.33583533 | X35: =F35*J35+G35*K35+H35*L35+M35*L35 -> 1257784.6
A36: 45971 | B36: 5214767 | C36: La Carolina | D36: 0.27 | E36: =SUM(F36:H36) -> 4876 | F36: 766 | G36: 2 | H36: 4108 | I36: T2-Ba | J36: 145.8675 | K36: 145.8675 | L36: 145.8675 | M36: 5400.1 | N36: =E36+M36 -> 10276.1 | O36: =J36*F36+G36*K36+H36*L36 -> 711249.93 | P36: 1470 | Q36: =(M36*L36)/P36 -> 535.84972 | R36: =Q36*P36 -> 787699.09 | S36: =IFERROR(__xludf.DUMMYFUNCTION("INDEX(IMPORTHTML(""https://www.bna.com.ar/Personas"", ""table"", 1), 2, 3)"),1465.0) -> 1465 | T36: =Q36*S36*(1+D36) -> 996975.19 | U36: =M36*0.2 -> 1080.02 | V36: =U36/22 -> 49.091818 | W36: =(M36*L36)/(M36*L36+H36*L36+K36*G36+J36*F36) -> 0.52550092 | X36: =F36*J36+G36*K36+H36*L36+M36*L36 -> 1498949
A37: 45972 | B37: 5068576 | C37: Facundo Alvarado | D37: 0.27 | E37: =SUM(F37:H37) -> 13501 | F37: 2929 | G37: 3482 | H37: 7090 | I37: T4-Ba | J37: 152.0913 | K37: 149.3017 | L37: 150.1043 | M37: 3529.5 | N37: =E37+M37 -> 17030.5 | O37: =J37*F37+G37*K37+H37*L37 -> 2029583.4 | P37: 1470 | Q37: =(M37*L37)/P37 -> 360.40349 | R37: =Q37*P37 -> 529793.13 | S37: =IFERROR(__xludf.DUMMYFUNCTION("INDEX(IMPORTHTML(""https://www.bna.com.ar/Personas"", ""table"", 1), 2, 3)"),1465.0) -> 1465 | T37: =Q37*S37*(1+D37) -> 670548.71 | U37: =M37*0.2 -> 705.9 | V37: =U37/22 -> 32.086364 | W37: =(M37*L37)/(M37*L37+H37*L37+K37*G37+J37*F37) -> 0.20700085 | X37: =F37*J37+G37*K37+H37*L37+M37*L37 -> 2559376.6
A38: 45973 | B38: 5019237 | C38: Etchart | D38: 0.27 | E38: =SUM(F38:H38) -> 3346 | F38: 809 | G38: 977 | H38: 1560 | I38: T4-Ba | J38: 152.0913 | K38: 149.3017 | L38: 150.1043 | M38: 1096.4 | N38: =E38+M38 -> 4442.4 | O38: =J38*F38+G38*K38+H38*L38 -> 503072.33 | P38: 1470 | Q38: =(M38*L38)/P38 -> 111.95534 | R38: =Q38*P38 -> 164574.35 | S38: =IFERROR(__xludf.DUMMYFUNCTION("INDEX(IMPORTHTML(""https://www.bna.com.ar/Personas"", ""table"", 1), 2, 3)"),1465.0) -> 1465 | T38: =Q38*S38*(1+D38) -> 208298.51 | U38: =M38*0.2 -> 219.28 | V38: =U38/22 -> 9.9672727 | W38: =(M38*L38)/(M38*L38+H38*L38+K38*G38+J38*F38) -> 0.24649917 | X38: =F38*J38+G38*K38+H38*L38+M38*L38 -> 667646.69
A39: 45974 | B39: 5272486 | C39: Linea C | D39: 0.27 | E39: =SUM(F39:H39) -> 4054 | H39: 4054 | I39: T1-G2 | J39: 195.1016 | K39: 195.1016 | L39: 195.1016 | M39: 1105.9 | N39: =E39+M39 -> 5159.9 | O39: =J39*F39+G39*K39+H39*L39 -> 790941.89 | P39: 1470 | Q39: =(M39*L39)/P39 -> 146.77746 | R39: =Q39*P39 -> 215762.86 | S39: =IFERROR(__xludf.DUMMYFUNCTION("INDEX(IMPORTHTML(""https://www.bna.com.ar/Personas"", ""table"", 1), 2, 3)"),1465.0) -> 1465 | T39: =Q39*S39*(1+D39) -> 273086.79 | U39: =M39*0.2 -> 221.18 | V39: =U39/22 -> 10.053636 | W39: =(M39*L39)/(M39*L39+H39*L39+K39*G39+J39*F39) -> 0.21432586 | X39: =F39*J39+G39*K39+H39*L39+M39*L39 -> 1006704.7
A40: 45975 | B40: 5238577 | C40: Agustín Lanús | D40: 0.27 | E40: =SUM(F40:H40) -> 6333 | H40: 6333 | I40: T2-Ba | J40: 145.8675 | K40: 145.8675 | L40: 145.8675 | M40: 1722.9 | N40: =E40+M40 -> 8055.9 | O40: =J40*F40+G40*K40+H40*L40 -> 923778.88 | P40: 1470 | Q40: =(M40*L40)/P40 -> 170.96266 | R40: =Q40*P40 -> 251315.12 | S40: =IFERROR(__xludf.DUMMYFUNCTION("INDEX(IMPORTHTML(""https://www.bna.com.ar/Personas"", ""table"", 1), 2, 3)"),1465.0) -> 1465 | T40: =Q40*S40*(1+D40) -> 318084.58 | U40: =M40*0.2 -> 344.58 | V40: =U40/22 -> 15.662727 | W40: =(M40*L40)/(M40*L40+H40*L40+K40*G40+J40*F40) -> 0.2138681 | X40: =F40*J40+G40*K40+H40*L40+M40*L40 -> 1175094
A41: 45976 | B41: 5253773 | C41: Ivan BV | D41: 0.27 | E41: =SUM(F41:H41) -> 517 | F41: 173 | G41: 74 | H41: 270 | I41: T1-R2-N1 | J41: 233.1878 | K41: 233.1878 | L41: 233.1878 | M41: 253.6 | N41: =E41+M41 -> 770.6 | O41: =J41*F41+G41*K41+H41*L41 -> 120558.09 | P41: 1470 | Q41: =(M41*L41)/P41 -> 40.228861 | R41: =Q41*P41 -> 59136.426 | S41: =IFERROR(__xludf.DUMMYFUNCTION("INDEX(IMPORTHTML(""https://www.bna.com.ar/Personas"", ""table"", 1), 2, 3)"),1465.0) -> 1465 | T41: =Q41*S41*(1+D41) -> 74847.808 | U41: =M41*0.2 -> 50.72 | V41: =U41/22 -> 2.3054545 | W41: =(M41*L41)/(M41*L41+H41*L41+K41*G41+J41*F41) -> 0.32909421 | X41: =F41*J41+G41*K41+H41*L41+M41*L41 -> 179694.52
...

Sheet LineaC
A1: =Datos!A1 -> Fecha | B1: =Datos!B1 -> NIS | C1: =Datos!C1 -> Cliente | D1: =Datos!D1 -> IVA | E1: =Datos!E1 -> Consumo [kWh] | F1: =Datos!F1 -> Consumo hs punta [kWh] | G1: =Datos!G1 -> Consumo hs valle [kWh] | H1: =Datos!H1 -> Consumo hs resto[kWh] | ... X1: =Datos!X1 -> SIN PANELES S/IVA
A2: =IFERROR(__xludf.DUMMYFUNCTION("FILTER(Datos!1:1247,Datos!B:B=5272486)"),45992.0) -> 45992 | B2: =IFERROR(__xludf.DUMMYFUNCTION("""COMPUTED_VALUE"""),5272486.0) -> 5272486 | C2: =IFERROR(__xludf.DUMMYFUNCTION("""COMPUTED_VALUE"""),"Linea C") -> Linea C | D2: =IFERROR(__xludf.DUMMYFUNCTION("""COMPUTED_VALUE"""),0.27) -> 0.27 | E2: =IFERROR(__xludf.DUMMYFUNCTION("""COMPUTED_VALUE"""),4539.0) -> 4539 | F2: =IFERROR(__xludf.DUMMYFUNCTION("""COMPUTED_VALUE"""),0.0) -> 0 | G2: =IFERROR(__xludf.DUMMYFUNCTION("""COMPUTED_VALUE"""),0.0) -> 0 | H2: =IFERROR(__xludf.DUMMYFUNCTION("""COMPUTED_VALUE"""),4539.0) -> 4539 | I2: =IFERROR(__xludf.DUMMYFUNCTION("""COMPUTED_VALUE"""),"T1-G2") -> T1-G2 | J2: =IFERROR(__xludf.DUMMYFUNCTION("""COMPUTED_VALUE"""),195.2987) -> 195.2987 | K2: =IFERROR(__xludf.DUMMYFUNCTION("""COMPUTED_VALUE"""),195.2987) -> 195.2987 | L2: =IFERROR(__xludf.DUMMYFUNCTION("""COMPUTED_VALUE"""),195.2987) -> 195.2987 | M2: =IFERROR(__xludf.DUMMYFUNCTION("""COMPUTED_VALUE"""),1113.6) -> 1113.6 | N2: =IFERROR(__xludf.DUMMYFUNCTION("""COMPUTED_VALUE"""),5652.6) -> 5652.6 | O2: =IFERROR(__xludf.DUMMYFUNCTION("""COMPUTED_VALUE"""),886460.7993) -> 886460.8 | P2: =IFERROR(__xludf.DUMMYFUNCTION("""COMPUTED_VALUE"""),1470.0) -> 1470 | Q2: =IFERROR(__xludf.DUMMYFUNCTION("""COMPUTED_VALUE"""),147.94872946938773) -> 147.94873 | R2: =IFERROR(__xludf.DUMMYFUNCTION("""COMPUTED_VALUE"""),217484.63231999998) -> 217484.63 | S2: =IFERROR(__xludf.DUMMYFUNCTION("""COMPUTED_VALUE"""),1465.0) -> 1465 | T2: =IFERROR(__xludf.DUMMYFUNCTION("""COMPUTED_VALUE"""),275266.0086142694) -> 275266.01 | U2: =IFERROR(__xludf.DUMMYFUNCTION("""COMPUTED_VALUE"""),222.72) -> 222.72 | V2: =IFERROR(__xludf.DUMMYFUNCTION("""COMPUTED_VALUE"""),10.123636363636363) -> 10.123636 | W2: =IFERROR(__xludf.DUMMYFUNCTION("""COMPUTED_VALUE"""),0.19700668718819658) -> 0.19700669 | X2: =IFERROR(__xludf.DUMMYFUNCTION("""COMPUTED_VALUE"""),1103945.43162) -> 1103945.4
A3: =IFERROR(__xludf.DUMMYFUNCTION("""COMPUTED_VALUE"""),45974.0) -> 45974 | B3: =IFERROR(__xludf.DUMMYFUNCTION("""COMPUTED_VALUE"""),5272486.0) -> 5272486 | C3: =IFERROR(__xludf.DUMMYFUNCTION("""COMPUTED_VALUE"""),"Linea C") -> Linea C | D3: =IFERROR(__xludf.DUMMYFUNCTION("""COMPUTED_VALUE"""),0.27) -> 0.27 | E3: =IFERROR(__xludf.DUMMYFUNCTION("""COMPUTED_VALUE"""),4054.0) -> 4054 | H3: =IFERROR(__xludf.DUMMYFUNCTION("""COMPUTED_VALUE"""),4054.0) -> 4054 | I3: =IFERROR(__xludf.DUMMYFUNCTION("""COMPUTED_VALUE"""),"T1-G2") -> T1-G2 | J3: =IFERROR(__xludf.DUMMYFUNCTION("""COMPUTED_VALUE"""),195.1016) -> 195.1016 | K3: =IFERROR(__xludf.DUMMYFUNCTION("""COMPUTED_VALUE"""),195.1016) -> 195.1016 | L3: =IFERROR(__xludf.DUMMYFUNCTION("""COMPUTED_VALUE"""),195.1016) -> 195.1016 | M3: =IFERROR(__xludf.DUMMYFUNCTION("""COMPUTED_VALUE"""),1105.9) -> 1105.9 | N3: =IFERROR(__xludf.DUMMYFUNCTION("""COMPUTED_VALUE"""),5159.9) -> 5159.9 | O3: =IFERROR(__xludf.DUMMYFUNCTION("""COMPUTED_VALUE"""),790941.8864) -> 790941.89 | P3: =IFERROR(__xludf.DUMMYFUNCTION("""COMPUTED_VALUE"""),1470.0) -> 1470 | Q3: =IFERROR(__xludf.DUMMYFUNCTION("""COMPUTED_VALUE"""),146.77745540136056) -> 146.77746 | R3: =IFERROR(__xludf.DUMMYFUNCTION("""COMPUTED_VALUE"""),215762.85944000003) -> 215762.86 | S3: =IFERROR(__xludf.DUMMYFUNCTION("""COMPUTED_VALUE"""),1465.0) -> 1465 | T3: =IFERROR(__xludf.DUMMYFUNCTION("""COMPUTED_VALUE"""),273086.79464700137) -> 273086.79 | U3: =IFERROR(__xludf.DUMMYFUNCTION("""COMPUTED_VALUE"""),221.18000000000004) -> 221.18 | V3: =IFERROR(__xludf.DUMMYFUNCTION("""COMPUTED_VALUE"""),10.053636363636365) -> 10.053636 | W3: =IFERROR(__xludf.DUMMYFUNCTION("""COMPUTED_VALUE"""),0.21432585902827575) -> 0.21432586 | X3: =IFERROR(__xludf.DUMMYFUNCTION("""COMPUTED_VALUE"""),1006704.74584) -> 1006704.7
A4: =IFERROR(__xludf.DUMMYFUNCTION("""COMPUTED_VALUE"""),45932.0) -> 45932 | B4: =IFERROR(__xludf.DUMMYFUNCTION("""COMPUTED_VALUE"""),5272486.0) -> 5272486 | C4: =IFERROR(__xludf.DUMMYFUNCTION("""COMPUTED_VALUE"""),"Linea C") -> Linea C | D4: =IFERROR(__xludf.DUMMYFUNCTION("""COMPUTED_VALUE"""),0.27) -> 0.27 | E4: =IFERROR(__xludf.DUMMYFUNCTION("""COMPUTED_VALUE"""),2726.0) -> 2726 | H4: =IFERROR(__xludf.DUMMYFUNCTION("""COMPUTED_VALUE"""),5990.0) -> 5990 | I4: =IFERROR(__xludf.DUMMYFUNCTION("""COMPUTED_VALUE"""),"T1-G2") -> T1-G2 | J4: =IFERROR(__xludf.DUMMYFUNCTION("""COMPUTED_VALUE"""),207.4306) -> 207.4306 | K4: =IFERROR(__xludf.DUMMYFUNCTION("""COMPUTED_VALUE"""),207.4306) -> 207.4306 | L4: =IFERROR(__xludf.DUMMYFUNCTION("""COMPUTED_VALUE"""),207.4306) -> 207.4306 | M4: =IFERROR(__xludf.DUMMYFUNCTION("""COMPUTED_VALUE"""),106.2) -> 106.2 | N4: =IFERROR(__xludf.DUMMYFUNCTION("""COMPUTED_VALUE"""),2832.2) -> 2832.2 | O4: =IFERROR(__xludf.DUMMYFUNCTION("""COMPUTED_VALUE"""),1242509.294) -> 1242509.3 | P4: =IFERROR(__xludf.DUMMYFUNCTION("""COMPUTED_VALUE"""),1450.0) -> 1450 | Q4: =IFERROR(__xludf.DUMMYFUNCTION("""COMPUTED_VALUE"""),15.192503255172415) -> 15.192503 | R4: =IFERROR(__xludf.DUMMYFUNCTION("""COMPUTED_VALUE"""),22029.12972) -> 22029.13 | S4: =IFERROR(__xludf.DUMMYFUNCTION("""COMPUTED_VALUE"""),1465.0) -> 1465 | T4: =IFERROR(__xludf.DUMMYFUNCTION("""COMPUTED_VALUE"""),28266.41193141104) -> 28266.412 | U4: =IFERROR(__xludf.DUMMYFUNCTION("""COMPUTED_VALUE"""),21.240000000000002) -> 21.24 | V4: =IFERROR(__xludf.DUMMYFUNCTION("""COMPUTED_VALUE"""),0.9654545454545456) -> 0.96545455 | W4: =IFERROR(__xludf.DUMMYFUNCTION("""COMPUTED_VALUE"""),0.01742068829762803) -> 0.017420688 | X4: =IFERROR(__xludf.DUMMYFUNCTION("""COMPUTED_VALUE"""),1264538.42372) -> 1264538.4
A5: =IFERROR(__xludf.DUMMYFUNCTION("""COMPUTED_VALUE"""),45913.0) -> 45913 | B5: =IFERROR(__xludf.DUMMYFUNCTION("""COMPUTED_VALUE"""),5272486.0) -> 5272486 | C5: =IFERROR(__xludf.DUMMYFUNCTION("""COMPUTED_VALUE"""),"Linea C") -> Linea C | D5: =IFERROR(__xludf.DUMMYFUNCTION("""COMPUTED_VALUE"""),0.27) -> 0.27 | E5: =IFERROR(__xludf.DUMMYFUNCTION("""COMPUTED_VALUE"""),2726.0) -> 2726 | I5: =IFERROR(__xludf.DUMMYFUNCTION("""COMPUTED_VALUE"""),"T1-G2") -> T1-G2 | N5: =IFERROR(__xludf.DUMMYFUNCTION("""COMPUTED_VALUE"""),2726.0) -> 2726 | O5: =IFERROR(__xludf.DUMMYFUNCTION("""COMPUTED_VALUE"""),0.0) -> 0 | P5: =IFERROR(__xludf.DUMMYFUNCTION("""COMPUTED_VALUE"""),1425.0) -> 1425 | Q5: =IFERROR(__xludf.DUMMYFUNCTION("""COMPUTED_VALUE"""),0.0) -> 0 | R5: =IFERROR(__xludf.DUMMYFUNCTION("""COMPUTED_VALUE"""),0.0) -> 0 | S5: =IFERROR(__xludf.DUMMYFUNCTION("""COMPUTED_VALUE"""),1465.0) -> 1465 | T5: =IFERROR(__xludf.DUMMYFUNCTION("""COMPUTED_VALUE"""),0.0) -> 0 | U5: =IFERROR(__xludf.DUMMYFUNCTION("""COMPUTED_VALUE"""),0.0) -> 0 | V5: =IFERROR(__xludf.DUMMYFUNCTION("""COMPUTED_VALUE"""),0.0) -> 0 | W5: =IFERROR(__xludf.DUMMYFUNCTION("""COMPUTED_VALUE"""),"#DIV/0!") -> #DIV/0! | X5: =IFERROR(__xludf.DUMMYFUNCTION("""COMPUTED_VALUE"""),0.0) -> 0

Sheet LineaC Trimestral
A1: =Datos!A1 -> Fecha | B1: =Datos!B1 -> NIS | C1: =Datos!C1 -> Cliente | D1: =Datos!D1 -> IVA | E1: =Datos!E1 -> Consumo [kWh] | F1: =Datos!F1 -> Consumo hs punta [kWh] | G1: =Datos!G1 -> Consumo hs valle [kWh] | H1: =Datos!H1 -> Consumo hs resto[kWh] | ... X1: =Datos!X1 -> SIN PANELES S/IVA
A2: =LineaC!A2 -> 45992 | B2: =LineaC!B2 -> 5272486 | C2: =LineaC!C2 -> Linea C | D2: =LineaC!D2 -> 0.27 | E2: =LineaC!E2 -> 4539 | F2: =LineaC!F2 -> 0 | G2: =LineaC!G2 -> 0 | H2: =LineaC!H2 -> 4539 | ... X2: =LineaC!X2 -> 1103945.4
A3: =LineaC!A3 -> 45974 | B3: =LineaC!B3 -> 5272486 | C3: =LineaC!C3 -> Linea C | D3: =LineaC!D3 -> 0.27 | E3: =LineaC!E3 -> 4054 | F3: =LineaC!F3 | G3: =LineaC!G3 | H3: =LineaC!H3 -> 4054 | ... X3: =LineaC!X3 -> 1006704.7
A4: =LineaC!A4 -> 45932 | B4: =LineaC!B4 -> 5272486 | C4: =LineaC!C4 -> Linea C | D4: =LineaC!D4 -> 0.27 | E4: =LineaC!E4 -> 2726 | F4: =LineaC!F4 | G4: =LineaC!G4 | H4: =LineaC!H4 -> 5990 | ... X4: =LineaC!X4 -> 1264538.4

Sheet Cendis
A1: =Datos!A1 -> Fecha | B1: =Datos!B1 -> NIS | C1: =Datos!C1 -> Cliente | D1: =Datos!D1 -> IVA | E1: =Datos!E1 -> Consumo [kWh] | F1: =Datos!F1 -> Consumo hs punta [kWh] | G1: =Datos!G1 -> Consumo hs valle [kWh] | H1: =Datos!H1 -> Consumo hs resto[kWh] | ... X1: =Datos!X1 -> SIN PANELES S/IVA
A2: =IFERROR(__xludf.DUMMYFUNCTION("FILTER(Datos!1:1247,Datos!B:B=5238545)"),45993.0) -> 45993 | B2: =IFERROR(__xludf.DUMMYFUNCTION("""COMPUTED_VALUE"""),5238545.0) -> 5238545 | C2: =IFERROR(__xludf.DUMMYFUNCTION("""COMPUTED_VALUE"""),"Cendis ") -> Cendis | D2: =IFERROR(__xludf.DUMMYFUNCTION("""COMPUTED_VALUE"""),0.27) -> 0.27 | E2: =IFERROR(__xludf.DUMMYFUNCTION("""COMPUTED_VALUE"""),46318.0) -> 46318 | F2: =IFERROR(__xludf.DUMMYFUNCTION("""COMPUTED_VALUE"""),11250.0) -> 11250 | G2: =IFERROR(__xludf.DUMMYFUNCTION("""COMPUTED_VALUE"""),11963.0) -> 11963 | H2: =IFERROR(__xludf.DUMMYFUNCTION("""COMPUTED_VALUE"""),23105.0) -> 23105 | I2: =IFERROR(__xludf.DUMMYFUNCTION("""COMPUTED_VALUE"""),"T5-Ba") -> T5-Ba | J2: =IFERROR(__xludf.DUMMYFUNCTION("""COMPUTED_VALUE"""),168.7698) -> 168.7698 | K2: =IFERROR(__xludf.DUMMYFUNCTION("""COMPUTED_VALUE"""),165.9802) -> 165.9802 | L2: =IFERROR(__xludf.DUMMYFUNCTION("""COMPUTED_VALUE"""),166.7828) -> 166.7828 | M2: =IFERROR(__xludf.DUMMYFUNCTION("""COMPUTED_VALUE"""),13451.7) -> 13451.7 | N2: =IFERROR(__xludf.DUMMYFUNCTION("""COMPUTED_VALUE"""),59769.7) -> 59769.7 | O2: =IFERROR(__xludf.DUMMYFUNCTION("""COMPUTED_VALUE"""),7737797.976600001) -> 7737798 | P2: =IFERROR(__xludf.DUMMYFUNCTION("""COMPUTED_VALUE"""),1470.0) -> 1470 | Q2: =IFERROR(__xludf.DUMMYFUNCTION("""COMPUTED_VALUE"""),1526.19876922449) -> 1526.1988 | R2: =IFERROR(__xludf.DUMMYFUNCTION("""COMPUTED_VALUE"""),2243512.19076) -> 2243512.2 | S2: =IFERROR(__xludf.DUMMYFUNCTION("""COMPUTED_VALUE"""),1465.0) -> 1465 | T2: =IFERROR(__xludf.DUMMYFUNCTION("""COMPUTED_VALUE"""),2839569.120080625) -> 2839569.1 | U2: =IFERROR(__xludf.DUMMYFUNCTION("""COMPUTED_VALUE"""),2690.34) -> 2690.34 | V2: =IFERROR(__xludf.DUMMYFUNCTION("""COMPUTED_VALUE"""),122.28818181818183) -> 122.28818 | W2: =IFERROR(__xludf.DUMMYFUNCTION("""COMPUTED_VALUE"""),0.22477131289803373) -> 0.22477131 | X2: =IFERROR(__xludf.DUMMYFUNCTION("""COMPUTED_VALUE"""),9981310.16736) -> 9981310.2
A3: =IFERROR(__xludf.DUMMYFUNCTION("""COMPUTED_VALUE"""),45963.0) -> 45963 | B3: =IFERROR(__xludf.DUMMYFUNCTION("""COMPUTED_VALUE"""),5238545.0) -> 5238545 | C3: =IFERROR(__xludf.DUMMYFUNCTION("""COMPUTED_VALUE"""),"Cendis ") -> Cendis | D3: =IFERROR(__xludf.DUMMYFUNCTION("""COMPUTED_VALUE"""),0.27) -> 0.27 | E3: =IFERROR(__xludf.DUMMYFUNCTION("""COMPUTED_VALUE"""),35146.0) -> 35146 | F3: =IFERROR(__xludf.DUMMYFUNCTION("""COMPUTED_VALUE"""),9214.0) -> 9214 | G3: =IFERROR(__xludf.DUMMYFUNCTION("""COMPUTED_VALUE"""),9096.0) -> 9096 | H3: =IFERROR(__xludf.DUMMYFUNCTION("""COMPUTED_VALUE"""),16836.0) -> 16836 | I3: =IFERROR(__xludf.DUMMYFUNCTION("""COMPUTED_VALUE"""),"T5-Ba") -> T5-Ba | J3: =IFERROR(__xludf.DUMMYFUNCTION("""COMPUTED_VALUE"""),163.3724) -> 163.3724 | K3: =IFERROR(__xludf.DUMMYFUNCTION("""COMPUTED_VALUE"""),160.5827) -> 160.5827 | L3: =IFERROR(__xludf.DUMMYFUNCTION("""COMPUTED_VALUE"""),161.3854) -> 161.3854 | M3: =IFERROR(__xludf.DUMMYFUNCTION("""COMPUTED_VALUE"""),12463.3) -> 12463.3 | N3: =IFERROR(__xludf.DUMMYFUNCTION("""COMPUTED_VALUE"""),47609.3) -> 47609.3 | O3: =IFERROR(__xludf.DUMMYFUNCTION("""COMPUTED_VALUE"""),5683058.1272) -> 5683058.1 | P3: =IFERROR(__xludf.DUMMYFUNCTION("""COMPUTED_VALUE"""),1470.0) -> 1470 | Q3: =IFERROR(__xludf.DUMMYFUNCTION("""COMPUTED_VALUE"""),1368.2956842312924) -> 1368.2957 | R3: =IFERROR(__xludf.DUMMYFUNCTION("""COMPUTED_VALUE"""),2011394.6558199998) -> 2011394.7 | S3: =IFERROR(__xludf.DUMMYFUNCTION("""COMPUTED_VALUE"""),1465.0) -> 1465 | T3: =IFERROR(__xludf.DUMMYFUNCTION("""COMPUTED_VALUE"""),2545782.5352965314) -> 2545782.5 | U3: =IFERROR(__xludf.DUMMYFUNCTION("""COMPUTED_VALUE"""),2492.66) -> 2492.66 | V3: =IFERROR(__xludf.DUMMYFUNCTION("""COMPUTED_VALUE"""),113.30272727272727) -> 113.30273 | W3: =IFERROR(__xludf.DUMMYFUNCTION("""COMPUTED_VALUE"""),0.2614084084392219) -> 0.26140841 | X3: =IFERROR(__xludf.DUMMYFUNCTION("""COMPUTED_VALUE"""),7694452.78302) -> 7694452.8
A4: =IFERROR(__xludf.DUMMYFUNCTION("""COMPUTED_VALUE"""),45932.0) -> 45932 | B4: =IFERROR(__xludf.DUMMYFUNCTION("""COMPUTED_VALUE"""),5238545.0) -> 5238545 | C4: =IFERROR(__xludf.DUMMYFUNCTION("""COMPUTED_VALUE"""),"Cendis ") -> Cendis | D4: =IFERROR(__xludf.DUMMYFUNCTION("""COMPUTED_VALUE"""),0.27) -> 0.27 | E4: =IFERROR(__xludf.DUMMYFUNCTION("""COMPUTED_VALUE"""),27401.0) -> 27401 | F4: =IFERROR(__xludf.DUMMYFUNCTION("""COMPUTED_VALUE"""),7072.0) -> 7072 | G4: =IFERROR(__xludf.DUMMYFUNCTION("""COMPUTED_VALUE"""),7098.0) -> 7098 | H4: =IFERROR(__xludf.DUMMYFUNCTION("""COMPUTED_VALUE"""),13231.0) -> 13231 | I4: =IFERROR(__xludf.DUMMYFUNCTION("""COMPUTED_VALUE"""),"T5-Ba") -> T5-Ba | J4: =IFERROR(__xludf.DUMMYFUNCTION("""COMPUTED_VALUE"""),170.9156) -> 170.9156 | K4: =IFERROR(__xludf.DUMMYFUNCTION("""COMPUTED_VALUE"""),168.0814) -> 168.0814 | L4: =IFERROR(__xludf.DUMMYFUNCTION("""COMPUTED_VALUE"""),169.332) -> 169.332 | M4: =IFERROR(__xludf.DUMMYFUNCTION("""COMPUTED_VALUE"""),10226.1) -> 10226.1 | N4: =IFERROR(__xludf.DUMMYFUNCTION("""COMPUTED_VALUE"""),37627.1) -> 37627.1 | O4: =IFERROR(__xludf.DUMMYFUNCTION("""COMPUTED_VALUE"""),4642188.5923999995) -> 4642188.6 | P4: =IFERROR(__xludf.DUMMYFUNCTION("""COMPUTED_VALUE"""),1450.0) -> 1450 | Q4: =IFERROR(__xludf.DUMMYFUNCTION("""COMPUTED_VALUE"""),1194.2110104827586) -> 1194.211 | R4: =IFERROR(__xludf.DUMMYFUNCTION("""COMPUTED_VALUE"""),1731605.9652) -> 1731606 | S4: =IFERROR(__xludf.DUMMYFUNCTION("""COMPUTED_VALUE"""),1465.0) -> 1465 | T4: =IFERROR(__xludf.DUMMYFUNCTION("""COMPUTED_VALUE"""),2221889.295553697) -> 2221889.3 | U4: =IFERROR(__xludf.DUMMYFUNCTION("""COMPUTED_VALUE"""),2045.2200000000003) -> 2045.22 | V4: =IFERROR(__xludf.DUMMYFUNCTION("""COMPUTED_VALUE"""),92.96454545454547) -> 92.964545 | W4: =IFERROR(__xludf.DUMMYFUNCTION("""COMPUTED_VALUE"""),0.2716758360426386) -> 0.27167584 | X4: =IFERROR(__xludf.DUMMYFUNCTION("""COMPUTED_VALUE"""),6373794.557599999) -> 6373794.6

Sheet Cendis Trimestral 
A1: =Datos!A1 -> Fecha | B1: =Datos!B1 -> NIS | C1: =Datos!C1 -> Cliente | D1: =Datos!D1 -> IVA | E1: =Datos!E1 -> Consumo [kWh] | F1: =Datos!F1 -> Consumo hs punta [kWh] | G1: =Datos!G1 -> Consumo hs valle [kWh] | H1: =Datos!H1 -> Consumo hs resto[kWh] | ... X1: =Datos!X1 -> SIN PANELES S/IVA
A2: =Cendis!A2 -> 45993 | B2: =Cendis!B2 -> 5238545 | C2: =Cendis!C2 -> Cendis | D2: =Cendis!D2 -> 0.27 | E2: =Cendis!E2 -> 46318 | F2: =Cendis!F2 -> 11250 | G2: =Cendis!G2 -> 11963 | H2: =Cendis!H2 -> 23105 | ... X2: =Cendis!X2 -> 9981310.2
A3: =Cendis!A3 -> 45963 | B3: =Cendis!B3 -> 5238545 | C3: =Cendis!C3 -> Cendis | D3: =Cendis!D3 -> 0.27 | E3: =Cendis!E3 -> 35146 | F3: =Cendis!F3 -> 9214 | G3: =Cendis!G3 -> 9096 | H3: =Cendis!H3 -> 16836 | ... X3: =Cendis!X3 -> 7694452.8
A4: =Cendis!A4 -> 45932 | B4: =Cendis!B4 -> 5238545 | C4: =Cendis!C4 -> Cendis | D4: =Cendis!D4 -> 0.27 | E4: =Cendis!E4 -> 27401 | F4: =Cendis!F4 -> 7072 | G4: =Cendis!G4 -> 7098 | H4: =Cendis!H4 -> 13231 | ... X4: =Cendis!X4 -> 6373794.6

Sheet Tolaba
A1: =Datos!A1 -> Fecha | B1: =Datos!B1 -> NIS | C1: =Datos!C1 -> Cliente | D1: =Datos!D1 -> IVA | E1: =Datos!E1 -> Consumo [kWh] | F1: =Datos!F1 -> Consumo hs punta [kWh] | G1: =Datos!G1 -> Consumo hs valle [kWh] | H1: =Datos!H1 -> Consumo hs resto[kWh] | ... X1: =Datos!X1 -> SIN PANELES S/IVA
A2: =IFERROR(__xludf.DUMMYFUNCTION("FILTER(Datos!1:1247,Datos!B:B=3062898)"),45992.0) -> 45992 | B2: =IFERROR(__xludf.DUMMYFUNCTION("""COMPUTED_VALUE"""),3062898.0) -> 3062898 | C2: =IFERROR(__xludf.DUMMYFUNCTION("""COMPUTED_VALUE"""),"Tolaba") -> Tolaba | D2: =IFERROR(__xludf.DUMMYFUNCTION("""COMPUTED_VALUE"""),0.27) -> 0.27 | E2: =IFERROR(__xludf.DUMMYFUNCTION("""COMPUTED_VALUE"""),25661.0) -> 25661 | F2: =IFERROR(__xludf.DUMMYFUNCTION("""COMPUTED_VALUE"""),6829.0) -> 6829 | G2: =IFERROR(__xludf.DUMMYFUNCTION("""COMPUTED_VALUE"""),7919.0) -> 7919 | H2: =IFERROR(__xludf.DUMMYFUNCTION("""COMPUTED_VALUE"""),10913.0) -> 10913 | I2: =IFERROR(__xludf.DUMMYFUNCTION("""COMPUTED_VALUE"""),"T8") -> T8 | J2: =IFERROR(__xludf.DUMMYFUNCTION("""COMPUTED_VALUE"""),255.886) -> 255.886 | K2: =IFERROR(__xludf.DUMMYFUNCTION("""COMPUTED_VALUE"""),253.0963) -> 253.0963 | L2: =IFERROR(__xludf.DUMMYFUNCTION("""COMPUTED_VALUE"""),253.899) -> 253.899 | M2: =IFERROR(__xludf.DUMMYFUNCTION("""COMPUTED_VALUE"""),6284.5) -> 6284.5 | N2: =IFERROR(__xludf.DUMMYFUNCTION("""COMPUTED_VALUE"""),31945.5) -> 31945.5 | O2: =IFERROR(__xludf.DUMMYFUNCTION("""COMPUTED_VALUE"""),6522514.8807) -> 6522514.9 | P2: =IFERROR(__xludf.DUMMYFUNCTION("""COMPUTED_VALUE"""),1470.0) -> 1470 | Q2: =IFERROR(__xludf.DUMMYFUNCTION("""COMPUTED_VALUE"""),1085.4614051020408) -> 1085.4614 | R2: =IFERROR(__xludf.DUMMYFUNCTION("""COMPUTED_VALUE"""),1595628.2655) -> 1595628.3 | S2: =IFERROR(__xludf.DUMMYFUNCTION("""COMPUTED_VALUE"""),1465.0) -> 1465 | T2: =IFERROR(__xludf.DUMMYFUNCTION("""COMPUTED_VALUE"""),2019555.217262602) -> 2019555.2 | U2: =IFERROR(__xludf.DUMMYFUNCTION("""COMPUTED_VALUE"""),1256.9) -> 1256.9 | V2: =IFERROR(__xludf.DUMMYFUNCTION("""COMPUTED_VALUE"""),57.13181818181818) -> 57.131818 | W2: =IFERROR(__xludf.DUMMYFUNCTION("""COMPUTED_VALUE"""),0.19655089061183817) -> 0.19655089 | X2: =IFERROR(__xludf.DUMMYFUNCTION("""COMPUTED_VALUE"""),8118143.146199999) -> 8118143.1
A3: =IFERROR(__xludf.DUMMYFUNCTION("""COMPUTED_VALUE"""),45966.0) -> 45966 | B3: =IFERROR(__xludf.DUMMYFUNCTION("""COMPUTED_VALUE"""),3062898.0) -> 3062898 | C3: =IFERROR(__xludf.DUMMYFUNCTION("""COMPUTED_VALUE"""),"Tolaba ") -> Tolaba | D3: =IFERROR(__xludf.DUMMYFUNCTION("""COMPUTED_VALUE"""),0.27) -> 0.27 | E3: =IFERROR(__xludf.DUMMYFUNCTION("""COMPUTED_VALUE"""),7178.0) -> 7178 | F3: =IFERROR(__xludf.DUMMYFUNCTION("""COMPUTED_VALUE"""),1742.0) -> 1742 | G3: =IFERROR(__xludf.DUMMYFUNCTION("""COMPUTED_VALUE"""),1984.0) -> 1984 | H3: =IFERROR(__xludf.DUMMYFUNCTION("""COMPUTED_VALUE"""),3452.0) -> 3452 | I3: =IFERROR(__xludf.DUMMYFUNCTION("""COMPUTED_VALUE"""),"T8") -> T8 | J3: =IFERROR(__xludf.DUMMYFUNCTION("""COMPUTED_VALUE"""),253.749) -> 253.749 | K3: =IFERROR(__xludf.DUMMYFUNCTION("""COMPUTED_VALUE"""),251.0043) -> 251.0043 | L3: =IFERROR(__xludf.DUMMYFUNCTION("""COMPUTED_VALUE"""),251.807) -> 251.807 | M3: =IFERROR(__xludf.DUMMYFUNCTION("""COMPUTED_VALUE"""),1018.2) -> 1018.2 | N3: =IFERROR(__xludf.DUMMYFUNCTION("""COMPUTED_VALUE"""),2760.2) -> 2760.2 | O3: =IFERROR(__xludf.DUMMYFUNCTION("""COMPUTED_VALUE"""),1809261.0532) -> 1809261.1 | P3: =IFERROR(__xludf.DUMMYFUNCTION("""COMPUTED_VALUE"""),1470.0) -> 1470 | Q3: =IFERROR(__xludf.DUMMYFUNCTION("""COMPUTED_VALUE"""),174.4148893877551) -> 174.41489 | R3: =IFERROR(__xludf.DUMMYFUNCTION("""COMPUTED_VALUE"""),256389.88739999998) -> 256389.89 | S3: =IFERROR(__xludf.DUMMYFUNCTION("""COMPUTED_VALUE"""),1465.0) -> 1465 | T3: =IFERROR(__xludf.DUMMYFUNCTION("""COMPUTED_VALUE"""),324507.62245038775) -> 324507.62 | U3: =IFERROR(__xludf.DUMMYFUNCTION("""COMPUTED_VALUE"""),203.64000000000001) -> 203.64 | V3: =IFERROR(__xludf.DUMMYFUNCTION("""COMPUTED_VALUE"""),9.256363636363638) -> 9.2563636 | W3: =IFERROR(__xludf.DUMMYFUNCTION("""COMPUTED_VALUE"""),0.12412062578468734) -> 0.12412063 | X3: =IFERROR(__xludf.DUMMYFUNCTION("""COMPUTED_VALUE"""),2065650.9405999999) -> 2065650.9
A4: =IFERROR(__xludf.DUMMYFUNCTION("""COMPUTED_VALUE"""),45931.0) -> 45931 | B4: =IFERROR(__xludf.DUMMYFUNCTION("""COMPUTED_VALUE"""),3062898.0) -> 3062898 | C4: =IFERROR(__xludf.DUMMYFUNCTION("""COMPUTED_VALUE"""),"Tolaba ") -> Tolaba | D4: =IFERROR(__xludf.DUMMYFUNCTION("""COMPUTED_VALUE"""),0.27) -> 0.27 | E4: =IFERROR(__xludf.DUMMYFUNCTION("""COMPUTED_VALUE"""),1733.0) -> 1733 | F4: =IFERROR(__xludf.DUMMYFUNCTION("""COMPUTED_VALUE"""),377.0) -> 377 | G4: =IFERROR(__xludf.DUMMYFUNCTION("""COMPUTED_VALUE"""),386.0) -> 386 | H4: =IFERROR(__xludf.DUMMYFUNCTION("""COMPUTED_VALUE"""),970.0) -> 970 | I4: =IFERROR(__xludf.DUMMYFUNCTION("""COMPUTED_VALUE"""),"T8") -> T8 | J4: =IFERROR(__xludf.DUMMYFUNCTION("""COMPUTED_VALUE"""),250.4823) -> 250.4823 | K4: =IFERROR(__xludf.DUMMYFUNCTION("""COMPUTED_VALUE"""),247.6481) -> 247.6481 | L4: =IFERROR(__xludf.DUMMYFUNCTION("""COMPUTED_VALUE"""),248.8987) -> 248.8987 | M4: =IFERROR(__xludf.DUMMYFUNCTION("""COMPUTED_VALUE"""),174.5) -> 174.5 | N4: =IFERROR(__xludf.DUMMYFUNCTION("""COMPUTED_VALUE"""),1907.5) -> 1907.5 | O4: =IFERROR(__xludf.DUMMYFUNCTION("""COMPUTED_VALUE"""),431455.7327) -> 431455.73 | P4: =IFERROR(__xludf.DUMMYFUNCTION("""COMPUTED_VALUE"""),1450.0) -> 1450 | Q4: =IFERROR(__xludf.DUMMYFUNCTION("""COMPUTED_VALUE"""),29.953671137931032) -> 29.953671 | R4: =IFERROR(__xludf.DUMMYFUNCTION("""COMPUTED_VALUE"""),43432.82315) -> 43432.823 | S4: =IFERROR(__xludf.DUMMYFUNCTION("""COMPUTED_VALUE"""),1465.0) -> 1465 | T4: =IFERROR(__xludf.DUMMYFUNCTION("""COMPUTED_VALUE"""),55730.302835677576) -> 55730.303 | U4: =IFERROR(__xludf.DUMMYFUNCTION("""COMPUTED_VALUE"""),34.9) -> 34.9 | V4: =IFERROR(__xludf.DUMMYFUNCTION("""COMPUTED_VALUE"""),1.5863636363636362) -> 1.5863636 | W4: =IFERROR(__xludf.DUMMYFUNCTION("""COMPUTED_VALUE"""),0.09145898045965724) -> 0.09145898 | X4: =IFERROR(__xludf.DUMMYFUNCTION("""COMPUTED_VALUE"""),474888.55585) -> 474888.56
A5: =IFERROR(__xludf.DUMMYFUNCTION("""COMPUTED_VALUE"""),45903.0) -> 45903 | B5: =IFERROR(__xludf.DUMMYFUNCTION("""COMPUTED_VALUE"""),3062898.0) -> 3062898 | C5: =IFERROR(__xludf.DUMMYFUNCTION("""COMPUTED_VALUE"""),"Tolaba ") -> Tolaba | D5: =IFERROR(__xludf.DUMMYFUNCTION("""COMPUTED_VALUE"""),0.27) -> 0.27 | E5: =IFERROR(__xludf.DUMMYFUNCTION("""COMPUTED_VALUE"""),1544.0) -> 1544 | F5: =IFERROR(__xludf.DUMMYFUNCTION("""COMPUTED_VALUE"""),168.0) -> 168 | G5: =IFERROR(__xludf.DUMMYFUNCTION("""COMPUTED_VALUE"""),278.0) -> 278 | H5: =IFERROR(__xludf.DUMMYFUNCTION("""COMPUTED_VALUE"""),1098.0) -> 1098 | I5: =IFERROR(__xludf.DUMMYFUNCTION("""COMPUTED_VALUE"""),"T2-Ba") -> T2-Ba | J5: =IFERROR(__xludf.DUMMYFUNCTION("""COMPUTED_VALUE"""),156.8264) -> 156.8264 | K5: =IFERROR(__xludf.DUMMYFUNCTION("""COMPUTED_VALUE"""),156.8264) -> 156.8264 | L5: =IFERROR(__xludf.DUMMYFUNCTION("""COMPUTED_VALUE"""),156.8264) -> 156.8264 | M5: =IFERROR(__xludf.DUMMYFUNCTION("""COMPUTED_VALUE"""),717.3) -> 717.3 | N5: =IFERROR(__xludf.DUMMYFUNCTION("""COMPUTED_VALUE"""),2261.3) -> 2261.3 | O5: =IFERROR(__xludf.DUMMYFUNCTION("""COMPUTED_VALUE"""),242139.9616) -> 242139.96 | P5: =IFERROR(__xludf.DUMMYFUNCTION("""COMPUTED_VALUE"""),1425.0) -> 1425 | Q5: =IFERROR(__xludf.DUMMYFUNCTION("""COMPUTED_VALUE"""),78.94145734736841) -> 78.941457 | R5: =IFERROR(__xludf.DUMMYFUNCTION("""COMPUTED_VALUE"""),112491.57671999998) -> 112491.58 | S5: =IFERROR(__xludf.DUMMYFUNCTION("""COMPUTED_VALUE"""),1465.0) -> 1465 | T5: =IFERROR(__xludf.DUMMYFUNCTION("""COMPUTED_VALUE"""),146874.5284676463) -> 146874.53 | U5: =IFERROR(__xludf.DUMMYFUNCTION("""COMPUTED_VALUE"""),143.46) -> 143.46 | V5: =IFERROR(__xludf.DUMMYFUNCTION("""COMPUTED_VALUE"""),6.520909090909091) -> 6.5209091 | W5: =IFERROR(__xludf.DUMMYFUNCTION("""COMPUTED_VALUE"""),0.31720691637553616) -> 0.31720692 | X5: =IFERROR(__xludf.DUMMYFUNCTION("""COMPUTED_VALUE"""),354631.53832) -> 354631.54
A6: =IFERROR(__xludf.DUMMYFUNCTION("""COMPUTED_VALUE"""),45871.0) -> 45871 | B6: =IFERROR(__xludf.DUMMYFUNCTION("""COMPUTED_VALUE"""),3062898.0) -> 3062898 | C6: =IFERROR(__xludf.DUMMYFUNCTION("""COMPUTED_VALUE"""),"Tolaba ") -> Tolaba | D6: =IFERROR(__xludf.DUMMYFUNCTION("""COMPUTED_VALUE"""),0.27) -> 0.27 | E6: =IFERROR(__xludf.DUMMYFUNCTION("""COMPUTED_VALUE"""),2018.0) -> 2018 | F6: =IFERROR(__xludf.DUMMYFUNCTION("""COMPUTED_VALUE"""),488.0) -> 488 | G6: =IFERROR(__xludf.DUMMYFUNCTION("""COMPUTED_VALUE"""),571.0) -> 571 | H6: =IFERROR(__xludf.DUMMYFUNCTION("""COMPUTED_VALUE"""),959.0) -> 959 | I6: =IFERROR(__xludf.DUMMYFUNCTION("""COMPUTED_VALUE"""),"T8") -> T8 | J6: =IFERROR(__xludf.DUMMYFUNCTION("""COMPUTED_VALUE"""),245.9868) -> 245.9868 | K6: =IFERROR(__xludf.DUMMYFUNCTION("""COMPUTED_VALUE"""),243.1367) -> 243.1367 | L6: =IFERROR(__xludf.DUMMYFUNCTION("""COMPUTED_VALUE"""),244.3947) -> 244.3947 | M6: =IFERROR(__xludf.DUMMYFUNCTION("""COMPUTED_VALUE"""),704.0) -> 704 | N6: =IFERROR(__xludf.DUMMYFUNCTION("""COMPUTED_VALUE"""),2722.0) -> 2722 | O6: =IFERROR(__xludf.DUMMYFUNCTION("""COMPUTED_VALUE"""),493247.1314) -> 493247.13 | P6: =IFERROR(__xludf.DUMMYFUNCTION("""COMPUTED_VALUE"""),1340.0) -> 1340 | Q6: =IFERROR(__xludf.DUMMYFUNCTION("""COMPUTED_VALUE"""),128.3984095522388) -> 128.39841 | R6: =IFERROR(__xludf.DUMMYFUNCTION("""COMPUTED_VALUE"""),172053.8688) -> 172053.87 | S6: =IFERROR(__xludf.DUMMYFUNCTION("""COMPUTED_VALUE"""),1465.0) -> 1465 | T6: =IFERROR(__xludf.DUMMYFUNCTION("""COMPUTED_VALUE"""),238891.66089241792) -> 238891.66 | U6: =IFERROR(__xludf.DUMMYFUNCTION("""COMPUTED_VALUE"""),140.8) -> 140.8 | V6: =IFERROR(__xludf.DUMMYFUNCTION("""COMPUTED_VALUE"""),6.4) -> 6.4 | W6: =IFERROR(__xludf.DUMMYFUNCTION("""COMPUTED_VALUE"""),0.25861056686864725) -> 0.25861057 | X6: =IFERROR(__xludf.DUMMYFUNCTION("""COMPUTED_VALUE"""),665301.0002) -> 665301
A7: =IFERROR(__xludf.DUMMYFUNCTION("""COMPUTED_VALUE"""),45840.0) -> 45840 | B7: =IFERROR(__xludf.DUMMYFUNCTION("""COMPUTED_VALUE"""),3062898.0) -> 3062898 | C7: =IFERROR(__xludf.DUMMYFUNCTION("""COMPUTED_VALUE"""),"Tolaba ") -> Tolaba | D7: =IFERROR(__xludf.DUMMYFUNCTION("""COMPUTED_VALUE"""),0.27) -> 0.27 | E7: =IFERROR(__xludf.DUMMYFUNCTION("""COMPUTED_VALUE"""),2546.0) -> 2546 | F7: =IFERROR(__xludf.DUMMYFUNCTION("""COMPUTED_VALUE"""),533.0) -> 533 | G7: =IFERROR(__xludf.DUMMYFUNCTION("""COMPUTED_VALUE"""),628.0) -> 628 | H7: =IFERROR(__xludf.DUMMYFUNCTION("""COMPUTED_VALUE"""),1385.0) -> 1385 | I7: =IFERROR(__xludf.DUMMYFUNCTION("""COMPUTED_VALUE"""),"T8") -> T8 | J7: =IFERROR(__xludf.DUMMYFUNCTION("""COMPUTED_VALUE"""),236.6792) -> 236.6792 | K7: =IFERROR(__xludf.DUMMYFUNCTION("""COMPUTED_VALUE"""),233.8316) -> 233.8316 | L7: =IFERROR(__xludf.DUMMYFUNCTION("""COMPUTED_VALUE"""),235.0884) -> 235.0884 | M7: =IFERROR(__xludf.DUMMYFUNCTION("""COMPUTED_VALUE"""),118.3) -> 118.3 | N7: =IFERROR(__xludf.DUMMYFUNCTION("""COMPUTED_VALUE"""),2664.3) -> 2664.3 | O7: =IFERROR(__xludf.DUMMYFUNCTION("""COMPUTED_VALUE"""),598593.6924) -> 598593.69 | P7: =IFERROR(__xludf.DUMMYFUNCTION("""COMPUTED_VALUE"""),1280.0) -> 1280 | Q7: =IFERROR(__xludf.DUMMYFUNCTION("""COMPUTED_VALUE"""),21.727310718749997) -> 21.727311 | R7: =IFERROR(__xludf.DUMMYFUNCTION("""COMPUTED_VALUE"""),27810.95772) -> 27810.958 | S7: =IFERROR(__xludf.DUMMYFUNCTION("""COMPUTED_VALUE"""),1465.0) -> 1465 | T7: =IFERROR(__xludf.DUMMYFUNCTION("""COMPUTED_VALUE"""),40424.74795777031) -> 40424.748 | U7: =IFERROR(__xludf.DUMMYFUNCTION("""COMPUTED_VALUE"""),23.66) -> 23.66 | V7: =IFERROR(__xludf.DUMMYFUNCTION("""COMPUTED_VALUE"""),1.0754545454545454) -> 1.0754545 | W7: =IFERROR(__xludf.DUMMYFUNCTION("""COMPUTED_VALUE"""),0.04439775106182922) -> 0.044397751 | X7: =IFERROR(__xludf.DUMMYFUNCTION("""COMPUTED_VALUE"""),626404.65012) -> 626404.65

Sheet Tolaba Trimestral
A1: =Datos!A1 -> Fecha | B1: =Datos!B1 -> NIS | C1: =Datos!C1 -> Cliente | D1: =Datos!D1 -> IVA | E1: =Datos!E1 -> Consumo [kWh] | F1: =Datos!F1 -> Consumo hs punta [kWh] | G1: =Datos!G1 -> Consumo hs valle [kWh] | H1: =Datos!H1 -> Consumo hs resto[kWh] | ... X1: =Datos!X1 -> SIN PANELES S/IVA
A2: =Tolaba!A2 -> 45992 | B2: =Tolaba!B2 -> 3062898 | C2: =Tolaba!C2 -> Tolaba | D2: =Tolaba!D2 -> 0.27 | E2: =Tolaba!E2 -> 25661 | F2: =Tolaba!F2 -> 6829 | G2: =Tolaba!G2 -> 7919 | H2: =Tolaba!H2 -> 10913 | ... X2: =Tolaba!X2 -> 8118143.1
A3: =Tolaba!A3 -> 45966 | B3: =Tolaba!B3 -> 3062898 | C3: =Tolaba!C3 -> Tolaba | D3: =Tolaba!D3 -> 0.27 | E3: =Tolaba!E3 -> 7178 | F3: =Tolaba!F3 -> 1742 | G3: =Tolaba!G3 -> 1984 | H3: =Tolaba!H3 -> 3452 | ... X3: =Tolaba!X3 -> 2065650.9
A4: =Tolaba!A4 -> 45931 | B4: =Tolaba!B4 -> 3062898 | C4: =Tolaba!C4 -> Tolaba | D4: =Tolaba!D4 -> 0.27 | E4: =Tolaba!E4 -> 1733 | F4: =Tolaba!F4 -> 377 | G4: =Tolaba!G4 -> 386 | H4: =Tolaba!H4 -> 970 | ... X4: =Tolaba!X4 -> 474888.56

Sheet Robles
A1: =Datos!A1 -> Fecha | B1: =Datos!B1 -> NIS | C1: =Datos!C1 -> Cliente | D1: =Datos!D1 -> IVA | E1: =Datos!E1 -> Consumo [kWh] | F1: =Datos!F1 -> Consumo hs punta [kWh] | G1: =Datos!G1 -> Consumo hs valle [kWh] | H1: =Datos!H1 -> Consumo hs resto[kWh] | ... X1: =Datos!X1 -> SIN PANELES S/IVA
A2: =IFERROR(__xludf.DUMMYFUNCTION("FILTER(Datos!1:1247,Datos!B:B=3011513)"),45992.0) -> 45992 | B2: =IFERROR(__xludf.DUMMYFUNCTION("""COMPUTED_VALUE"""),3011513.0) -> 3011513 | C2: =IFERROR(__xludf.DUMMYFUNCTION("""COMPUTED_VALUE"""),"Robles") -> Robles | D2: =IFERROR(__xludf.DUMMYFUNCTION("""COMPUTED_VALUE"""),0.27) -> 0.27 | E2: =IFERROR(__xludf.DUMMYFUNCTION("""COMPUTED_VALUE"""),28047.0) -> 28047 | F2: =IFERROR(__xludf.DUMMYFUNCTION("""COMPUTED_VALUE"""),7969.0) -> 7969 | G2: =IFERROR(__xludf.DUMMYFUNCTION("""COMPUTED_VALUE"""),9368.0) -> 9368 | H2: =IFERROR(__xludf.DUMMYFUNCTION("""COMPUTED_VALUE"""),10710.0) -> 10710 | I2: =IFERROR(__xludf.DUMMYFUNCTION("""COMPUTED_VALUE"""),"T8") -> T8 | J2: =IFERROR(__xludf.DUMMYFUNCTION("""COMPUTED_VALUE"""),255.886) -> 255.886 | K2: =IFERROR(__xludf.DUMMYFUNCTION("""COMPUTED_VALUE"""),253.0963) -> 253.0963 | L2: =IFERROR(__xludf.DUMMYFUNCTION("""COMPUTED_VALUE"""),253.899) -> 253.899 | M2: =IFERROR(__xludf.DUMMYFUNCTION("""COMPUTED_VALUE"""),10816.3) -> 10816.3 | N2: =IFERROR(__xludf.DUMMYFUNCTION("""COMPUTED_VALUE"""),38863.3) -> 38863.3 | O2: =IFERROR(__xludf.DUMMYFUNCTION("""COMPUTED_VALUE"""),7129419.9624) -> 7129420 | P2: =IFERROR(__xludf.DUMMYFUNCTION("""COMPUTED_VALUE"""),1470.0) -> 1470 | Q2: =IFERROR(__xludf.DUMMYFUNCTION("""COMPUTED_VALUE"""),1868.1957508163264) -> 1868.1958 | R2: =IFERROR(__xludf.DUMMYFUNCTION("""COMPUTED_VALUE"""),2746247.7537) -> 2746247.8 | S2: =IFERROR(__xludf.DUMMYFUNCTION("""COMPUTED_VALUE"""),1465.0) -> 1465 | T2: =IFERROR(__xludf.DUMMYFUNCTION("""COMPUTED_VALUE"""),3475871.6041813157) -> 3475871.6 | U2: =IFERROR(__xludf.DUMMYFUNCTION("""COMPUTED_VALUE"""),2163.2599999999998) -> 2163.26 | V2: =IFERROR(__xludf.DUMMYFUNCTION("""COMPUTED_VALUE"""),98.32999999999998) -> 98.33 | W2: =IFERROR(__xludf.DUMMYFUNCTION("""COMPUTED_VALUE"""),0.2780822353128463) -> 0.27808224 | X2: =IFERROR(__xludf.DUMMYFUNCTION("""COMPUTED_VALUE"""),9875667.7161) -> 9875667.7
A3: =IFERROR(__xludf.DUMMYFUNCTION("""COMPUTED_VALUE"""),45967.0) -> 45967 | B3: =IFERROR(__xludf.DUMMYFUNCTION("""COMPUTED_VALUE"""),3011513.0) -> 3011513 | C3: =IFERROR(__xludf.DUMMYFUNCTION("""COMPUTED_VALUE"""),"Robles ") -> Robles | D3: =IFERROR(__xludf.DUMMYFUNCTION("""COMPUTED_VALUE"""),0.27) -> 0.27 | E3: =IFERROR(__xludf.DUMMYFUNCTION("""COMPUTED_VALUE"""),691.0) -> 691 | F3: =IFERROR(__xludf.DUMMYFUNCTION("""COMPUTED_VALUE"""),208.0) -> 208 | G3: =IFERROR(__xludf.DUMMYFUNCTION("""COMPUTED_VALUE"""),207.0) -> 207 | H3: =IFERROR(__xludf.DUMMYFUNCTION("""COMPUTED_VALUE"""),276.0) -> 276 | I3: =IFERROR(__xludf.DUMMYFUNCTION("""COMPUTED_VALUE"""),"T8") -> T8 | J3: =IFERROR(__xludf.DUMMYFUNCTION("""COMPUTED_VALUE"""),253.749) -> 253.749 | K3: =IFERROR(__xludf.DUMMYFUNCTION("""COMPUTED_VALUE"""),251.0043) -> 251.0043 | L3: =IFERROR(__xludf.DUMMYFUNCTION("""COMPUTED_VALUE"""),251.807) -> 251.807 | M3: =IFERROR(__xludf.DUMMYFUNCTION("""COMPUTED_VALUE"""),632.2) -> 632.2 | N3: =IFERROR(__xludf.DUMMYFUNCTION("""COMPUTED_VALUE"""),1323.2) -> 1323.2 | O3: =IFERROR(__xludf.DUMMYFUNCTION("""COMPUTED_VALUE"""),103969.2291) -> 103969.23 | P3: =IFERROR(__xludf.DUMMYFUNCTION("""COMPUTED_VALUE"""),1470.0) -> 1470 | Q3: =IFERROR(__xludf.DUMMYFUNCTION("""COMPUTED_VALUE"""),64.55506017687075) -> 64.55506 | R3: =IFERROR(__xludf.DUMMYFUNCTION("""COMPUTED_VALUE"""),94895.93846) -> 94895.938 | S3: =IFERROR(__xludf.DUMMYFUNCTION("""COMPUTED_VALUE"""),1465.0) -> 1465 | T3: =IFERROR(__xludf.DUMMYFUNCTION("""COMPUTED_VALUE"""),120107.91721207688) -> 120107.92 | U3: =IFERROR(__xludf.DUMMYFUNCTION("""COMPUTED_VALUE"""),126.44000000000001) -> 126.44 | V3: =IFERROR(__xludf.DUMMYFUNCTION("""COMPUTED_VALUE"""),5.747272727272728) -> 5.7472727 | W3: =IFERROR(__xludf.DUMMYFUNCTION("""COMPUTED_VALUE"""),0.477187330613687) -> 0.47718733 | X3: =IFERROR(__xludf.DUMMYFUNCTION("""COMPUTED_VALUE"""),198865.16756) -> 198865.17
